<robot name="abb_irb4600_60_205">
  <link name="world" />
  <joint name="world_to_base_link" type="fixed">
    <parent link="world" />
    <child link="base_link" />
    <origin xyz="0 0 0" rpy="0 0 0" />
  </joint>
  <link name="base_link">
    <inertial>
      <origin xyz="0 0 0" rpy="0 0 0" />
      <mass value="1.0" />
      <inertia ixx="0.1" ixy="0.0" ixz="0.0" iyy="0.1" iyz="0.0" izz="0.1" />
    </inertial>
    <collision name="collision">
      <geometry>
        <mesh filename="file:///home/gen/abb4600_rws_ws/src/abb_irb4600_support/meshes/irb4600/collision/base_link.stl" />
      </geometry>
      <material name="">
        <color rgba="1 1 0 1" />
      </material>
    </collision>
    <visual name="visual">
      <geometry>
        <mesh filename="file:///home/gen/abb4600_rws_ws/src/abb_irb4600_support/meshes/irb4600/visual/base_link.dae" />
      </geometry>
      <material name="">
        <color rgba="0.7725490 0.7803922 0.7686275 1" />
      </material>
    </visual>
  </link>
  <link name="link_1">
    <inertial>
      <origin xyz="0 0 0" rpy="0 0 0" />
      <mass value="1.0" />
      <inertia ixx="0.1" ixy="0.0" ixz="0.0" iyy="0.1" iyz="0.0" izz="0.1" />
    </inertial>
    <collision name="collision">
      <geometry>
        <mesh filename="file:///home/gen/abb4600_rws_ws/src/abb_irb4600_support/meshes/irb4600/collision/link_1.stl" />
      </geometry>
      <material name="">
        <color rgba="1 1 0 1" />
      </material>
    </collision>
    <visual name="visual">
      <geometry>
        <mesh filename="file:///home/gen/abb4600_rws_ws/src/abb_irb4600_support/meshes/irb4600/visual/link_1.dae" />
      </geometry>
      <material name="">
        <color rgba="0.7725490 0.7803922 0.7686275 1" />
      </material>
    </visual>
  </link>
  <link name="link_2">
    <inertial>
      <origin xyz="0 0 0" rpy="0 0 0" />
      <mass value="1.0" />
      <inertia ixx="0.1" ixy="0.0" ixz="0.0" iyy="0.1" iyz="0.0" izz="0.1" />
    </inertial>
    <collision name="collision">
      <geometry>
        <mesh filename="file:///home/gen/abb4600_rws_ws/src/abb_irb4600_support/meshes/irb4600_60_205/collision/link_2.stl" />
      </geometry>
      <material name="">
        <color rgba="1 1 0 1" />
      </material>
    </collision>
    <visual name="visual">
      <geometry>
        <mesh filename="file:///home/gen/abb4600_rws_ws/src/abb_irb4600_support/meshes/irb4600_60_205/visual/link_2.dae" />
      </geometry>
      <material name="">
        <color rgba="0.7725490 0.7803922 0.7686275 1" />
      </material>
    </visual>
  </link>
  <link name="link_3">
    <inertial>
      <origin xyz="0 0 0" rpy="0 0 0" />
      <mass value="1.0" />
      <inertia ixx="0.1" ixy="0.0" ixz="0.0" iyy="0.1" iyz="0.0" izz="0.1" />
    </inertial>
    <collision name="collision">
      <geometry>
        <mesh filename="file:///home/gen/abb4600_rws_ws/src/abb_irb4600_support/meshes/irb4600_60_205/collision/link_3.stl" />
      </geometry>
      <material name="">
        <color rgba="1 1 0 1" />
      </material>
    </collision>
    <visual name="visual">
      <geometry>
        <mesh filename="file:///home/gen/abb4600_rws_ws/src/abb_irb4600_support/meshes/irb4600_60_205/visual/link_3.dae" />
      </geometry>
      <material name="">
        <color rgba="0.7725490 0.7803922 0.7686275 1" />
      </material>
    </visual>
  </link>
  <link name="link_4">
    <inertial>
      <origin xyz="0 0 0" rpy="0 0 0" />
      <mass value="1.0" />
      <inertia ixx="0.1" ixy="0.0" ixz="0.0" iyy="0.1" iyz="0.0" izz="0.1" />
    </inertial>
    <collision name="collision">
      <geometry>
        <mesh filename="file:///home/gen/abb4600_rws_ws/src/abb_irb4600_support/meshes/irb4600_60_205/collision/link_4.stl" />
      </geometry>
      <material name="">
        <color rgba="1 1 0 1" />
      </material>
    </collision>
    <visual name="visual">
      <geometry>
        <mesh filename="file:///home/gen/abb4600_rws_ws/src/abb_irb4600_support/meshes/irb4600_60_205/visual/link_4.dae" />
      </geometry>
      <material name="">
        <color rgba="0.7725490 0.7803922 0.7686275 1" />
      </material>
    </visual>
  </link>
  <link name="link_5">
    <inertial>
      <origin xyz="0 0 0" rpy="0 0 0" />
      <mass value="1.0" />
      <inertia ixx="0.1" ixy="0.0" ixz="0.0" iyy="0.1" iyz="0.0" izz="0.1" />
    </inertial>
    <collision name="collision">
      <geometry>
        <mesh filename="file:///home/gen/abb4600_rws_ws/src/abb_irb4600_support/meshes/irb4600_60_205/collision/link_5.stl" />
      </geometry>
      <material name="">
        <color rgba="1 1 0 1" />
      </material>
    </collision>
    <visual name="visual">
      <geometry>
        <mesh filename="file:///home/gen/abb4600_rws_ws/src/abb_irb4600_support/meshes/irb4600_60_205/visual/link_5.dae" />
      </geometry>
      <material name="">
        <color rgba="0.7725490 0.7803922 0.7686275 1" />
      </material>
    </visual>
  </link>
  <link name="link_6">
    <inertial>
      <origin xyz="0 0 0" rpy="0 0 0" />
      <mass value="1.0" />
      <inertia ixx="0.1" ixy="0.0" ixz="0.0" iyy="0.1" iyz="0.0" izz="0.1" />
    </inertial>
    <collision name="collision">
      <geometry>
        <mesh filename="file:///home/gen/abb4600_rws_ws/src/abb_irb4600_support/meshes/irb4600_60_205/collision/link_6.stl" />
      </geometry>
      <material name="">
        <color rgba="1 1 0 1" />
      </material>
    </collision>
    <visual name="visual">
      <geometry>
        <mesh filename="file:///home/gen/abb4600_rws_ws/src/abb_irb4600_support/meshes/irb4600_60_205/visual/link_6.dae" />
      </geometry>
      <material name="">
        <color rgba="0.7725490 0.7803922 0.7686275 1" />
      </material>
    </visual>
  </link>
  <joint name="joint_1" type="revolute">
    <origin rpy="0 0 0" xyz="0 0 0.495" />
    <axis xyz="0 0 1" />
    <parent link="base_link" />
    <child link="link_1" />
    <limit effort="0" lower="-3.141" upper="3.141" velocity="3.054" />
  </joint>
  <joint name="joint_2" type="revolute">
    <origin rpy="0 0 0" xyz="0.175 0 0" />
    <axis xyz="0 1 0" />
    <parent link="link_1" />
    <child link="link_2" />
    <limit effort="0" lower="-1.570" upper="2.617" velocity="3.054" />
  </joint>
  <joint name="joint_3" type="revolute">
    <origin rpy="0 0 0" xyz="0 0 0.9" />
    <axis xyz="0 1 0" />
    <parent link="link_2" />
    <child link="link_3" />
    <limit effort="0" lower="-3.141" upper="1.309" velocity="3.054" />
  </joint>
  <joint name="joint_4" type="revolute">
    <origin rpy="0 0 0" xyz="0 0 0.175" />
    <axis xyz="1 0 0" />
    <parent link="link_3" />
    <child link="link_4" />
    <limit effort="0" lower="-6.981" upper="6.981" velocity="4.363" />
  </joint>
  <joint name="joint_5" type="revolute">
    <origin rpy="0 0 0" xyz="0.960 0 0 " />
    <axis xyz="0 1 0" />
    <parent link="link_4" />
    <child link="link_5" />
    <limit effort="0" lower="-2.181" upper="2.094" velocity="4.363" />
  </joint>
  <joint name="joint_6" type="revolute">
    <origin rpy="0 0 0" xyz="0.135 0 0 " />
    <axis xyz="1 0 0" />
    <parent link="link_5" />
    <child link="link_6" />
    <limit effort="0" lower="-6.981" upper="6.981" velocity="6.283" />
  </joint>
  <link name="base">
    <inertial>
      <origin xyz="0 0 0" rpy="0 0 0" />
      <mass value="1.0" />
      <inertia ixx="0.1" ixy="0.0" ixz="0.0" iyy="0.1" iyz="0.0" izz="0.1" />
    </inertial>
  </link>
  <joint name="base_link-base" type="fixed">
    <origin rpy="0 0 0" xyz="0 0 0" />
    <parent link="base_link" />
    <child link="base" />
  </joint>
  <link name="flange">
    <inertial>
      <origin xyz="0 0 0" rpy="0 0 0" />
      <mass value="1.0" />
      <inertia ixx="0.1" ixy="0.0" ixz="0.0" iyy="0.1" iyz="0.0" izz="0.1" />
    </inertial>
  </link>
  <joint name="joint_6-flange" type="fixed">
    <origin rpy="0 0 0" xyz="0 0 0" />
    <parent link="link_6" />
    <child link="flange" />
  </joint>
  <link name="tool0">
    <inertial>
      <origin xyz="0 0 0" rpy="0 0 0" />
      <mass value="1.0" />
      <inertia ixx="0.1" ixy="0.0" ixz="0.0" iyy="0.1" iyz="0.0" izz="0.1" />
    </inertial>
  </link>
  <joint name="link_6-tool0" type="fixed">
    <origin rpy="0 1.5707963267948966 0" xyz="0 0 0" />
    <parent link="flange" />
    <child link="tool0" />
  </joint>
  <ros2_control name="ABBMultiInterfaceHardware" type="system">
    <hardware>
      <plugin>mock_components/GenericSystem</plugin>
      <param name="fake_sensor_commands">false</param>
      <param name="state_following_offset">0.0</param>
    </hardware>
    <joint name="joint_1">
      <command_interface name="position">
        <param name="min">-6.283185307179586</param>
        <param name="max">6.283185307179586</param>
      </command_interface>
      <command_interface name="velocity" />
      <state_interface name="position">
        <param name="initial_value">0.0</param>
      </state_interface>
      <state_interface name="velocity" />
    </joint>
    <joint name="joint_2">
      <command_interface name="position">
        <param name="min">-1.570</param>
        <param name="max">2.617</param>
      </command_interface>
      <command_interface name="velocity" />
      <state_interface name="position">
        <param name="initial_value">0.0</param>
      </state_interface>
      <state_interface name="velocity" />
    </joint>
    <joint name="joint_3">
      <command_interface name="position">
        <param name="min">-6.283185307179586</param>
        <param name="max">1.309</param>
      </command_interface>
      <command_interface name="velocity" />
      <state_interface name="position">
        <param name="initial_value">0.0</param>
      </state_interface>
      <state_interface name="velocity" />
    </joint>
    <joint name="joint_4">
      <command_interface name="position">
        <param name="min">-6.981</param>
        <param name="max">6.981</param>
      </command_interface>
      <command_interface name="velocity" />
      <state_interface name="position">
        <param name="initial_value">0.0</param>
      </state_interface>
      <state_interface name="velocity" />
    </joint>
    <joint name="joint_5">
      <command_interface name="position">
        <param name="min">-2.181</param>
        <param name="max">2.094</param>
      </command_interface>
      <command_interface name="velocity" />
      <state_interface name="position">
        <param name="initial_value">0.0</param>
      </state_interface>
      <state_interface name="velocity" />
    </joint>
    <joint name="joint_6">
      <command_interface name="position">
        <param name="min">-6.981</param>
        <param name="max">6.981</param>
      </command_interface>
      <command_interface name="velocity" />
      <state_interface name="position">
        <param name="initial_value">0.0</param>
      </state_interface>
      <state_interface name="velocity" />
    </joint>
  </ros2_control>
  <ros2_control name="GazeboSystem" type="system">
    <hardware>
      <plugin>gazebo_ros2_control/GazeboSystem</plugin>
    </hardware>
    <joint name="joint_1">
      <command_interface name="position" />
      <state_interface name="position" />
      <state_interface name="velocity" />
    </joint>
    <joint name="joint_2">
      <command_interface name="position" />
      <state_interface name="position" />
      <state_interface name="velocity" />
    </joint>
    <joint name="joint_3">
      <command_interface name="position" />
      <state_interface name="position" />
      <state_interface name="velocity" />
    </joint>
    <joint name="joint_4">
      <command_interface name="position" />
      <state_interface name="position" />
      <state_interface name="velocity" />
    </joint>
    <joint name="joint_5">
      <command_interface name="position" />
      <state_interface name="position" />
      <state_interface name="velocity" />
    </joint>
    <joint name="joint_6">
      <command_interface name="position" />
      <state_interface name="position" />
      <state_interface name="velocity" />
    </joint>
  </ros2_control>
  <gazebo>
    <plugin name="gazebo_ros2_control" filename="libgazebo_ros2_control.so">
      <parameters>/home/gen/abb4600_rws_ws/src/abb4600_gazebo/config/gazebo_controllers.yaml</parameters>
    </plugin>
  </gazebo>
</robot>